<mujoco model="alexander_v1_lower_body">
    <compiler angle="radian" eulerseq="XYZ" meshdir="../meshes" autolimits="true"/>

    <option iterations="3" ls_iterations="5" timestep="0.002" integrator="Euler">
        <flag eulerdamp="disable"/>
    </option>

    <default>
        <default class="alexander">
            <joint damping="2" frictionloss="0.3"/>
            <position inheritrange="2"/>
            <default class="alexander/spine">
                <joint axis="0 0 1" range="-0.5235987756 0.5235987756"/>
                <position forcerange="-150 150" kp="112"/>
            </default>
            <default class="alexander/hip">
                <default class="alexander/hip/x">
                    <joint axis="1 0 0" armature="0.004085"/>
                    <position forcerange="-150 150" kp="112"/>
                    <default class="alexander/hip/x/left">
                        <joint range="-0.3490658504 0.872664626"/>
                    </default>
                    <default class="alexander/hip/x/right">
                        <joint range="-0.872664626 0.3490658504"/>
                    </default>
                </default>
                <default class="alexander/hip/y">
                    <joint axis="0 1 0" range="-2.61799 0.785398" armature="0.01026"/>
                    <position forcerange="-200 200" kp="150"/>
                </default>
                <default class="alexander/hip/z">
                    <joint axis="0 0 1" armature="0.00124"/>
                    <position forcerange="-60 60" kp="45"/>
                    <default class="alexander/hip/z/left">
                        <joint range="-0.3490658504 1.0472"/>
                    </default>
                    <default class="alexander/hip/z/right">
                        <joint range="-1.0472 0.3490658504"/>
                    </default>
                </default>
            </default>
            <default class="alexander/knee">
                <joint axis="0 1 0" range="0.0 2.445206282" armature="0.01026"/>
                <position forcerange="-200 200" kp="150"/>
            </default>
            <default class="alexander/ankle">
                <joint armature="0.002301"/>
                <default class="alexander/ankle/x">
                    <joint axis="1 0 0" range="-1.0472 0.523599"/>
                    <position forcerange="-90 90" kp="67"/>
                </default>
                <default class="alexander/ankle/y">
                    <joint axis="0 1 0" range="-0.436332 0.436332"/>
                    <position forcerange="-180 180" kp="135"/>
                </default>
            </default>
            <default class="alexander/imu">
                <site group="4" rgba="0 0 1 0.4"/>
                <default class="alexander/imu/pelvis">
                    <site pos="-0.08687724 0.01225028 -0.08051472" euler="0.0 0.0 1.570796"/>
                </default>
                <default class="alexander/imu/hip">
                    <default class="alexander/imu/hip/left">
                        <site pos="-0.01922309 0.10145013 -0.01488788" euler="-1.570796 0 1.570796"/>
                    </default>
                    <default class="alexander/imu/hip/right">
                        <site pos="-0.01922309 -0.07694987 -0.01488788" euler="-1.570796 0 1.570796"/>
                    </default>
                </default>
                <default class="alexander/imu/thigh">
                    <default class="alexander/imu/thigh/left">
                        <site pos="0.10004 0.03746 -0.21194" euler="1.6947717585 0 1.570796"/>
                    </default>
                    <default class="alexander/imu/thigh/right">
                        <site pos="0.10003618 -0.033541826 -0.21194191" euler="1.6947717585 0 1.570796"/>
                    </default>
                </default>
                <default class="alexander/imu/shin">
                    <default class="alexander/imu/shin/left">
                        <site pos="0.05655120 0.00084826 -0.15664831" euler="1.403695170631842 0 -1.570796"/>
                    </default>
                    <default class="alexander/imu/shin/right">
                        <site pos="0.05673025 -0.00875818 -0.15674961" euler="1.403695170631842 0 -1.570796"/>
                    </default>
                </default>
                <default class="alexander/imu/foot">
                    <site pos="-0.03575526 0.01180178 -0.04979705" euler="0 0 1.570796"/>
                </default>
                <default class="alexander/imu/torso">
                    <site pos="0.04529 -0.02427 0.33757" euler="3.141592 0 0"/>
                </default>
            </default>
            <default class="alexander/visual">
                <geom contype="0" conaffinity="0" type="mesh"/>
            </default>
            <default class="alexander/collision">
                <geom group="3" contype="1" conaffinity="1" rgba="0 1 0 0.4"/>
                <default class="alexander/collision/foot">
                    <geom type="box" size="0.0985 0.045 0.01" pos="0.045 0.0 -0.0625" solimp="0.9 .95 0.01" condim="3" friction="0.8"/>
                </default>
            </default>
        </default>
    </default>

    <asset>
        <material name="metal" rgba=".9 .95 .95 1"/>
        <material name="black" rgba="0 0 0 1"/>
        <material name="white" rgba="1 1 1 1"/>
        <material name="gray" rgba="0.671705 0.692426 0.774270 1"/>
        <mesh name="left_ankle" file="legs/left_ankle.obj"/>
        <mesh name="left_foot" file="legs/left_foot.obj"/>
        <mesh name="left_hip_roll" file="legs/left_hip_roll.obj"/>
        <mesh name="left_hip_yaw" file="legs/left_hip_yaw.obj"/>
        <mesh name="left_shin" file="legs/left_shin.obj"/>
        <mesh name="left_thigh" file="legs/left_thigh.obj"/>
        <mesh name="pelvis" file="legs/pelvis.obj"/>
        <mesh name="right_ankle" file="legs/right_ankle.obj"/>
        <mesh name="right_foot" file="legs/right_foot.obj"/>
        <mesh name="right_hip_roll" file="legs/right_hip_roll.obj"/>
        <mesh name="right_hip_yaw" file="legs/right_hip_yaw.obj"/>
        <mesh name="right_shin" file="legs/right_shin.obj"/>
        <mesh name="right_thigh" file="legs/right_thigh.obj"/>
        <mesh name="head" file="head.obj"/>
        <mesh name="torso" file="torso.obj"/>
    </asset>

    <worldbody>
         <body name="pelvis_link" pos="0.0 0.0 1.0" childclass="alexander">
            <inertial 
                pos="-0.08354287 0.00005291 -0.03484828"
                mass="9.50083635"
                fullinertia="0.03428688 0.05178848 0.06001929 0.00001151 0.00015935 0.00004514"
            />
            <freejoint/>
            <geom mesh="pelvis" material="gray" class="alexander/visual"/>
            <site name="imu_pelvis" class="alexander/imu/pelvis"/>
            <body name="left_hip_roll" pos="-0.162 0.0595 -0.015">
                <inertial 
                    pos="0.04350911	0.08708606 -0.03525761"
                    mass="2.32977961"
                    fullinertia="0.00467452 0.00516613 0.00553124 -0.00058626 0.00013124 0.00048141"
                />
                <joint name="left_hip_x" class="alexander/hip/x/left"/>
                <geom mesh="left_hip_roll" material="gray" class="alexander/visual"/>
                <site name="imu_left_hip" class="alexander/imu/hip/left"/>
                <body name="left_hip_yaw" pos="0.06	0.1	-0.08">
                    <inertial 
                        pos="0.04549595	-0.00525571	-0.00937454"
                        mass="0.77281362"
                        fullinertia="0.00317639 0.00345182 0.00313245 0.00005807 0.00080598 0.00047441"
                    />
                    <joint name="left_hip_z" class="alexander/hip/z/left"/>
                    <geom mesh="left_hip_yaw" material="gray" class="alexander/visual"/> 
                    <body name="left_thigh" pos="0.1045	-0.0573	-0.0525">
                        <inertial 
                            pos="0.01417302 0.03268781 -0.10548314"
                            mass="7.75"
                            fullinertia="0.09264028 0.09733033 0.02803877 0.00038532 0.00916409 -0.0043516"
                        />
                        <joint name="left_hip_y" class="alexander/hip/y"/>
                        <geom mesh="left_thigh" material="gray" class="alexander/visual"/>
                        <site name="imu_left_thigh" class="alexander/imu/thigh/left"/>
                        <body name="left_shin" pos="0 0.018 -0.32">
                            <inertial 
                                pos="0.03807965	-0.00108105	-0.12410027"
                                mass="5.5"
                                fullinertia="0.08823148 0.09163264 0.01569601 -0.00054706 -0.00634132 0.00002714"
                            />
                            <joint name="left_knee_y" class="alexander/knee"/>
                            <geom mesh="left_shin" material="gray" class="alexander/visual"/>
                            <site name="imu_left_shin" class="alexander/imu/shin/left"/>
                            <body name="left_ankle" pos="0 0 -0.41">
                                <inertial 
                                    pos="2.94E-07 2.22E-07 -0.00462997"
                                    mass="0.05045632"
                                    fullinertia="0.00001733 0.00000714 0.00001851 2.12E-10 -1.26E-10 -2.02E-11"
                                />
                                <joint name="left_ankle_y" class="alexander/ankle/y"/>
                                <geom mesh="left_ankle" material="gray" class="alexander/visual"/>
                                <body name="left_foot" pos="0 0 -0.012">
                                    <inertial 
                                        pos="0.03793372	-0.00000219	-0.0443663"
                                        mass="1.28288609"
                                        fullinertia="0.00131328 0.00385286 0.00406301 0.00001057 0.00036242 -0.0000069"
                                    />
                                    <joint name="left_ankle_x" class="alexander/ankle/x"/>
                                    <geom mesh="left_foot" material="gray" class="alexander/visual"/>
                                    <geom name="left_foot_collision" class="alexander/collision/foot"/>
                                    <site name="imu_left_foot" class="alexander/imu/foot"/>
                                    <site name="left_foot_site" pos="0 0 0"/>
                                </body>
                            </body>
                        </body>
                    </body>
                </body>
            </body>
            <body name="right_hip_roll" pos="-0.162	-0.0595	-0.015">
                <inertial 
                    pos="0.04351957	-0.08688935	-0.03525357"
                    mass="2.32977248"
                    fullinertia="0.00467576 0.00516385 0.00552901 0.00061004 0.00013038 -0.00047381"
                />
                <joint name="right_hip_x" class="alexander/hip/x/right"/>
                <geom mesh="right_hip_roll" material="gray" class="alexander/visual"/>
                <site name="imu_right_hip" class="alexander/imu/hip/right"/>
                <body name="right_hip_yaw" pos="0.06 -0.1 -0.08">
                    <inertial 
                        pos="0.04549274	0.00525784	-0.00937505"
                        mass="0.77281055"
                        fullinertia="0.00317639 0.00345166 0.00313223 -0.00005765 0.00080587 -0.00047466"
                    />
                    <joint name="right_hip_z" class="alexander/hip/z/right"/>
                    <geom mesh="right_hip_yaw" material="gray" class="alexander/visual"/>
                    <body name="right_thigh" pos="0.1045	0.0573	-0.0525">
                        <inertial 
                            pos="0.01411846	-0.03282392	-0.10542795"
                            mass="7.75"
                            fullinertia="0.09273162 0.09738701 0.02802165 -0.00026689 0.00921343 0.00422485"
                        />
                        <joint name="right_hip_y" class="alexander/hip/y"/>
                        <geom mesh="right_thigh" material="gray" class="alexander/visual"/>
                        <site name="imu_right_thigh" class="alexander/imu/thigh/right"/>
                        <body name="right_shin" pos="0 -0.018 -0.32">
                            <inertial 
                                pos="0.03807648	0.00113375 -0.12408765"
                                mass="5.5"
                                fullinertia="0.08705693 0.090231 0.01554032 0.00057277 -0.00674654 0.00028332"
                            />
                            <joint name="right_knee_y" class="alexander/knee"/>
                            <geom mesh="right_shin" material="gray" class="alexander/visual"/>
                            <site name="imu_right_shin" class="alexander/imu/shin/right"/>
                            <body name="right_ankle" pos="0 0 -0.41">
                                <inertial 
                                    pos="2.94E-07 2.22E-07 -0.00462997"
                                    mass="0.05045632"
                                    fullinertia="0.00001733 0.00000714 0.00001851 2.12E-10 -1.26E-10 -2.02E-11"
                                />
                                <joint name="right_ankle_y" class="alexander/ankle/y"/>
                                <geom mesh="right_ankle" material="gray" class="alexander/visual"/>
                                <body name="right_foot" pos="0 0 -0.012">
                                    <inertial 
                                        pos="0.03793372	-0.00000219	-0.0443663"
                                        mass="1.28288609"
                                        fullinertia="0.00131328 0.00385286 0.00406301 0.00001057 0.00036242 -0.0000069"
                                    />
                                    <joint name="right_ankle_x" class="alexander/ankle/x"/>
                                    <geom mesh="right_foot" material="gray" class="alexander/visual"/>
                                    <geom name="right_foot_collision" class="alexander/collision/foot"/>
                                    <site name="imu_right_foot" class="alexander/imu/foot"/>
                                    <site name="right_foot_site" pos="0 0 0"/>
                                </body>
                            </body>
                        </body>
                    </body>
                </body>
            </body>
            <body name="torso" pos="0.0 0 0.018">
                <inertial 
                    pos="-0.034 0.0 0.297"
                    mass="4.208"
                    fullinertia="0.077 0.068 0.033 9.64E-06 0.008 7.24E-06"
                />
                <joint name="spine_z" class="alexander/spine"/>
                <geom mesh="torso" material="gray" class="alexander/visual"/>
                <site name="imu_torso" class="alexander/imu/torso"/>
            </body>
        </body>
    </worldbody>

    <actuator>
        <position class="alexander/hip/x/left" name="left_hip_x" joint="left_hip_x"/>
        <position class="alexander/hip/z/left" name="left_hip_z" joint="left_hip_z"/>
        <position class="alexander/hip/y" name="left_hip_y" joint="left_hip_y"/>
        <position class="alexander/knee" name="left_knee" joint="left_knee_y"/>
        <position class="alexander/ankle/y" name="left_ankle_y" joint="left_ankle_y"/>
        <position class="alexander/ankle/x" name="left_ankle_x" joint="left_ankle_x"/>
        <position class="alexander/hip/x/right" name="right_hip_x" joint="right_hip_x"/>
        <position class="alexander/hip/z/right" name="right_hip_z" joint="right_hip_z"/>
        <position class="alexander/hip/y" name="right_hip_y" joint="right_hip_y"/>
        <position class="alexander/knee" name="right_knee" joint="right_knee_y"/>
        <position class="alexander/ankle/y" name="right_ankle_y" joint="right_ankle_y"/>
        <position class="alexander/ankle/x" name="right_ankle_x" joint="right_ankle_x"/>
        <position class="alexander/spine" name="spine_z" joint="spine_z"/>
    </actuator>

    <sensor>
        <!-- Pelvis IMU: -->
         <gyro name="imu_pelvis_gyro" site="imu_pelvis"/>
         <accelerometer name="imu_pelvis_accelerometer" site="imu_pelvis"/>

        <!-- Left Hip IMU: -->
         <gyro name="imu_left_hip_gyro" site="imu_left_hip"/>
         <accelerometer name="imu_left_hip_accelerometer" site="imu_left_hip"/>

         <!-- Left Thight IMU: -->
        <gyro name="imu_left_thigh_gyro" site="imu_left_thigh"/>
        <accelerometer name="imu_left_thigh_accelerometer" site="imu_left_thigh"/>

        <!-- Left Shin IMU: -->
        <gyro name="imu_left_shin_gyro" site="imu_left_shin"/>
        <accelerometer name="imu_left_shin_accelerometer" site="imu_left_shin"/>

        <!-- Left Foot IMU: -->
        <gyro name="imu_left_foot_gyro" site="imu_left_foot"/>
        <accelerometer name="imu_left_foot_accelerometer" site="imu_left_foot"/>

        <!-- Right Hip IMU: -->
         <gyro name="imu_right_hip_gyro" site="imu_right_hip"/>
         <accelerometer name="imu_right_hip_accelerometer" site="imu_right_hip"/>

         <!-- Right Thight IMU: -->
        <gyro name="imu_right_thigh_gyro" site="imu_right_thigh"/>
        <accelerometer name="imu_right_thigh_accelerometer" site="imu_right_thigh"/>

        <!-- Right Shin IMU: -->
        <gyro name="imu_right_shin_gyro" site="imu_right_shin"/>
        <accelerometer name="imu_right_shin_accelerometer" site="imu_right_shin"/>

        <!-- Right Foot IMU: -->
        <gyro name="imu_right_foot_gyro" site="imu_right_foot"/>
        <accelerometer name="imu_right_foot_accelerometer" site="imu_right_foot"/>

        <!-- Torso IMU: -->
        <gyro name="imu_torso_gyro" site="imu_torso"/>
        <accelerometer name="imu_torso_accelerometer" site="imu_torso"/>

        <!-- Additional Sensors for training: -->
        <!-- Pelvis IMU: -->
        <framequat name="imu_pelvis_orientation" objtype="site" objname="imu_pelvis"/>
        <velocimeter name="imu_pelvis_linear_velocity" site="imu_pelvis"/>
        <framepos name="imu_pelvis_position" objtype="site" objname="imu_pelvis"/>

        <!-- Globals: -->
        <framezaxis name="upvector" objtype="site" objname="imu_pelvis"/>
        <framexaxis name="forwardvector" objtype="site" objname="imu_pelvis"/>
        <framelinvel name="global_linear_velocity" objtype="site" objname="imu_pelvis"/>
        <frameangvel name="global_angular_velocity" objtype="site" objname="imu_pelvis"/>
        <framelinvel name="left_foot_global_linear_velocity" objtype="site" objname="left_foot_site"/>
        <framelinvel name="right_foot_global_linear_velocity" objtype="site" objname="right_foot_site"/>
    </sensor>

</mujoco>