<mujoco model="Alexander">
  <default>
    <joint limited="true" damping="0.01" armature="0.01" frictionloss="0.01" />
    <geom condim="4" contype="1" conaffinity="15" friction="0.9 0.2 0.2" solref="0.001 2" />
    <motor ctrllimited="true" />
    <equality solref="0.001 2" />
    
    <!-- Defaults for visual and collision meshes -->
    <default class="visual">
      <geom group="2" material="default_material" type="mesh" contype="1" conaffinity="0"/>
    </default>
    <default class="collision">
      <geom group="3" type="mesh" contype="1"/>
    </default>
  </default>

  <compiler angle="radian" meshdir="../meshes/" eulerseq="zyx" autolimits="true" />

  <asset>
    <!-- Scene assets -->
    <texture name="texplane" type="2d" builtin="checker" rgb1=".0 .0 .0" rgb2=".8 .8 .8" width="100" height="100" />
    <material name="matplane" reflectance="0." texture="texplane" texrepeat="1 1" texuniform="true" />
    <material name="gray" rgba="0.5 0.5 0.5 1.0" />
    <material name="default_material" rgba="0.7 0.7 0.7 1" />

    <!-- Robot assets -->
    <!-- Lower body -->
    <mesh name="pelvis.obj" file="legs/pelvis.obj" />
    <mesh name="left_hip_roll.obj" file="legs/left_hip_roll.obj" />
    <mesh name="left_hip_yaw.obj" file="legs/left_hip_yaw.obj" />
    <mesh name="left_thigh.obj" file="legs/left_thigh.obj" />
    <mesh name="left_shin.obj" file="legs/left_shin.obj" />
    <mesh name="left_ankle.obj" file="legs/left_ankle.obj" />
    <mesh name="left_foot.obj" file="legs/left_foot.obj" />
    <mesh name="right_hip_roll.obj" file="legs/right_hip_roll.obj" />
    <mesh name="right_hip_yaw.obj" file="legs/right_hip_yaw.obj" />
    <mesh name="right_thigh.obj" file="legs/right_thigh.obj" />
    <mesh name="right_shin.obj" file="legs/right_shin.obj" />
    <mesh name="right_ankle.obj" file="legs/right_ankle.obj" />
    <mesh name="right_foot.obj" file="legs/right_foot.obj" />

    <!-- Upper body-->
    <mesh name="torso.obj" file="torso.obj" />
    <mesh name="LeftShoulderPitchLink.obj" file="cycloidal_arm/LeftShoulderPitchLink.obj" />
    <mesh name="LeftShoulderRollLink_shortBicep.obj" file="cycloidal_arm/LeftShoulderRollLink_shortBicep.obj" />
    <mesh name="LeftShoulderYawLink.obj" file="cycloidal_arm/LeftShoulderYawLink.obj" />
    <mesh name="LeftElbowPitchLink.obj" file="cycloidal_arm/LeftElbowPitchLink.obj" />
    <mesh name="LeftWristYawLink.obj" file="cycloidal_arm/LeftWristYawLink.obj" />
    <mesh name="LeftWristRollLink.obj" file="cycloidal_arm/LeftWristRollLink.obj" />
    <mesh name="nub.obj" file="cycloidal_arm/nub.obj" />
    <mesh name="wristmesh.obj" file="wristmesh.obj" />
    <mesh name="head.obj" file="head.obj"/>
    <mesh name="head_0.obj" file="head_0.obj" />
    <mesh name="head_1.obj" file="head_1.obj" />
    <mesh name="RightShoulderPitchLink.obj" file="cycloidal_arm/RightShoulderPitchLink.obj" />
    <mesh name="RightShoulderRollLink_shortBicep.obj" file="cycloidal_arm/RightShoulderRollLink_shortBicep.obj" />
    <mesh name="RightShoulderYawLink.obj" file="cycloidal_arm/RightShoulderYawLink.obj" />
    <mesh name="RightElbowPitchLink.obj" file="cycloidal_arm/RightElbowPitchLink.obj" />
    <mesh name="RightWristYawLink.obj" file="cycloidal_arm/RightWristYawLink.obj" />
    <mesh name="RightWristRollLink.obj" file="cycloidal_arm/RightWristRollLink.obj" />
  </asset>

  <worldbody>
    <light directional="true" diffuse="0.4 0.4 0.4" specular="0.1 0.1 0.1" pos="0 0 5.0" dir="0 0 -1" castshadow="false" />
    <light directional="true" diffuse="0.6 0.6 0.6" specular="0.2 0.2 0.2" pos="0 0 4" dir="0 0 -1" />
    <geom name="ground" type="plane" pos="0 0 0" size="10 10 0.001" quat="1 0 0 0" material="matplane" condim="3" conaffinity="15" />
    <body name="root" pos="0 0 0.9395" quat="1 0 0 0">
      <freejoint name="root" />
      <site name="root_site" pos="0 0 0" quat="1 0 0 0" />
      <body name="PELVIS_LINK" pos="0 0 0" quat="1 0 0 0">
        <inertial pos="-0.08354287 0.00005291 -0.03484828" quat="1.0 0.0 0.0 0.0" mass="9.50083635" diaginertia="0.03428688 0.05178848 0.06001929" />
        <geom name="PELVIS_LINK_visual_0" class="visual" pos="0.0 0.0 0.0" quat="1.0 0.0 0.0 0.0" mesh="pelvis.obj" />
        
        <!-- Left leg -->
        <body name="LEFT_HIP_X_LINK" pos="-0.162 0.0595 -0.015" quat="1.0 0.0 0.0 0.0">
          <joint name="LEFT_HIP_X" type="hinge" range="-0.3490658504 0.872664626" axis="1 0 0" />
          <inertial pos="0.04350911 0.08708606 -0.03525761" quat="1.0 0.0 0.0 0.0" mass="2.32977961" diaginertia="0.00467452 0.00516613 0.00553124" />
          <geom name="LEFT_HIP_X_LINK_visual_0" class="visual" pos="0.0 0.0 0.0" quat="1.0 0.0 0.0 0.0" mesh="left_hip_roll.obj" />
          <body name="LEFT_HIP_Z_LINK" pos="0.06 0.1 -0.08" quat="1.0 0.0 0.0 0.0">
            <joint name="LEFT_HIP_Z" type="hinge" range="-0.3490658504 1.0472" axis="0 0 1" />
            <inertial pos="0.04549595 -0.00525571 -0.00937454" quat="1.0 0.0 0.0 0.0" mass="0.77281362" diaginertia="0.00317639 0.00345182 0.00313245" />
            <geom name="LEFT_HIP_Z_LINK_visual_0" class="visual" pos="0 0 0" quat="1.0 0.0 0.0 0.0" mesh="left_hip_yaw.obj" />
            <body name="LEFT_THIGH" pos="0.1045 -0.0573 -0.0525" quat="1.0 0.0 0.0 0.0">
              <joint name="LEFT_HIP_Y" type="hinge" range="-2.61799 0.785398" axis="0 1 0" />
              <inertial pos="0.01417302 0.03268781 -0.10548314" quat="1.0 0.0 0.0 0.0" mass="7.75" diaginertia="0.09264028 0.09733033 0.02803877" />
              <geom name="LEFT_THIGH_visual_0" class="visual" pos="0 0 0" quat="1.0 0.0 0.0 0.0" mesh="left_thigh.obj" />
              <body name="LEFT_SHIN" pos="0 0.018 -0.32" quat="1.0 0.0 0.0 0.0">
                <joint name="LEFT_KNEE_Y" type="hinge" range="0 2.445206282" axis="0 1 0" />
                <inertial pos="0.03807965 -0.00108105 -0.12410027" quat="1.0 0.0 0.0 0.0" mass="5.5" diaginertia="0.08823148 0.09163264 0.01569601" />
                <geom name="LEFT_SHIN_visual_0" class="visual" pos="0 0 0" quat="1.0 0.0 0.0 0.0" mesh="left_shin.obj" />

                <!-- Left foot -->
                <body name="LEFT_ANKLE_Y_LINK" pos="0 0 -0.41" quat="1.0 0.0 0.0 0.0">
                  <joint name="LEFT_ANKLE_Y" type="hinge" range="-1.0472 0.523599" axis="0 1 0" />
                  <inertial pos="2.94E-07 2.22E-07 -0.00462997" quat="1.0 0.0 0.0 0.0" mass="0.05045632" diaginertia="1.733e-05 7.14e-06 1.851e-05" />
                  <geom name="LEFT_ANKLE_Y_LINK_visual_0" class="visual" pos="0 0 0" quat="1.0 0.0 0.0 0.0" mesh="left_ankle.obj" />
                  <body name="LEFT_FOOT" pos="0 0 -0.012" quat="1.0 0.0 0.0 0.0">
                    <joint name="LEFT_ANKLE_X" type="hinge" range="-0.436332 0.436332" axis="1 0 0" />
                    <inertial pos="0.03793372 -0.00000219 -0.0443663" quat="1.0 0.0 0.0 0.0" mass="1.28288609" diaginertia="0.00131328 0.00385286 0.00406301" />
                    <geom name="LEFT_FOOT_visual_0" class="visual" pos="0 0 0" quat="1.0 0.0 0.0 0.0" mesh="left_foot.obj" />
                    <body name="LEFT_FOOT_IMU_LINK" pos="-0.03575526 0.01180178 -0.04979705" quat="0.7071068967259818 0.0 0.0 0.7071066656470943">
                      <inertial pos="0 0 0" quat="1.0 0.0 0.0 0.0" mass="0" diaginertia="0.0 0.0 0.0" />
                      <site name="LEFT_FOOT_IMU_LINK_site" pos="-0.04979705 0.01180178 -0.03575526" quat="0.7071069 0.0 0.0 0.7071067" size="0.01" />
                    </body>
                  </body>
                </body>
                <body name="LEFT_SHIN_IMU_LINK" pos="0.05655120 0.00084826 -0.15664831" quat="0.5399826309812834 0.456529212248219 -0.45652906305682667 -0.5399824545177442">
                  <inertial pos="0 0 0" quat="1.0 0.0 0.0 0.0" mass="0" diaginertia="0.0 0.0 0.0" />
                  <site name="LEFT_SHIN_IMU_LINK_site" pos="-0.15664831 0.00084826 0.0565512" quat="0.5399826 0.4565292 0.4565291 -0.5399825" size="0.01" />
                </body>
              </body>
              <body name="LEFT_THIGH_IMU_LINK" pos="0.10004 0.03746 -0.21194" quat="0.4680657519331888 0.5300137878061918 0.5300136146004192 0.46806559897171474">
                <inertial pos="0 0 0" quat="1.0 0.0 0.0 0.0" mass="0" diaginertia="0.0 0.0 0.0" />
                <site name="LEFT_THIGH_IMU_LINK_site" pos="-0.21194 0.03746 0.10004" quat="0.7071069 0.0 0.0 0.7071067" size="0.01" />
              </body>
            </body>
          </body>
          <body name="LEFT_HIP_X_IMU_LINK" pos="-0.01922309 0.10145013 -0.01488788" quat="0.5000001633974483 -0.4999999999999733 -0.49999983660255165 0.4999999999999733">
            <inertial pos="0 0 0" quat="1.0 0.0 0.0 0.0" mass="0" diaginertia="0.0 0.0 0.0" />
            <site name="LEFT_HIP_X_IMU_LINK_site" pos="-0.01488788 0.10145013 -0.01922309" quat="0.5 -0.5 0.5 0.5" size="0.01" />
          </body>
        </body>

        <!-- Right leg -->
        <body name="RIGHT_HIP_X_LINK" pos="-0.162 -0.0595 -0.015" quat="1.0 0.0 0.0 0.0">
          <joint name="RIGHT_HIP_X" type="hinge" range="-0.872664626 0.3490658504" axis="1 0 0" />
          <inertial pos="0.04351957 -0.08688935 -0.03525357" quat="1.0 0.0 0.0 0.0" mass="2.32977248" diaginertia="0.00467576 0.00516385 0.00552901" />
          <geom name="RIGHT_HIP_X_LINK_visual_0" class="visual" pos="0.0 0.0 0.0" quat="1.0 0.0 0.0 0.0" mesh="right_hip_roll.obj" />
          <body name="RIGHT_HIP_Z_LINK" pos="0.06 -0.1 -0.08" quat="1.0 0.0 0.0 0.0">
            <joint name="RIGHT_HIP_Z" type="hinge" range="-1.0472 0.3490658504" axis="0 0 1" />
            <inertial pos="0.04549274 0.00525784 -0.00937505" quat="1.0 0.0 0.0 0.0" mass="0.77281055" diaginertia="0.00317639 0.00345166 0.00313223" />
            <geom name="RIGHT_HIP_Z_LINK_visual_0" class="visual" pos="0 0 0" quat="1.0 0.0 0.0 0.0" mesh="right_hip_yaw.obj" />
            <body name="RIGHT_THIGH" pos="0.1045 0.0573 -0.0525" quat="1.0 0.0 0.0 0.0">
              <joint name="RIGHT_HIP_Y" type="hinge" range="-2.61799 0.785398" axis="0 1 0" />
              <inertial pos="0.01411846 -0.03282392 -0.10542795" quat="1.0 0.0 0.0 0.0" mass="7.75" diaginertia="0.09273162 0.09738701 0.02802165" />
              <geom name="RIGHT_THIGH_visual_0" class="visual" pos="0 0 0" quat="1.0 0.0 0.0 0.0" mesh="right_thigh.obj" />
              <body name="RIGHT_SHIN" pos="0 -0.018 -0.32" quat="1.0 0.0 0.0 0.0">
                <joint name="RIGHT_KNEE_Y" type="hinge" range="0 2.445206282" axis="0 1 0" />
                <inertial pos="0.03807648 0.00113375 -0.12408765" quat="1.0 0.0 0.0 0.0" mass="5.5" diaginertia="0.08705693 0.090231 0.01554032" />
                <geom name="RIGHT_SHIN_visual_0" class="visual" pos="0 0 0" quat="1.0 0.0 0.0 0.0" mesh="right_shin.obj" />

                <!-- Right foot -->
                <body name="RIGHT_ANKLE_Y_LINK" pos="0 0 -0.41" quat="1.0 0.0 0.0 0.0">
                  <joint name="RIGHT_ANKLE_Y" type="hinge" range="-1.0472 0.523599" axis="0 1 0" />
                  <inertial pos="2.94E-07 2.22E-07 -0.00462997" quat="1.0 0.0 0.0 0.0" mass="0.05045632" diaginertia="1.733e-05 7.14e-06 1.851e-05" />
                  <geom name="RIGHT_ANKLE_Y_LINK_visual_0" class="visual" pos="0 0 0" quat="1.0 0.0 0.0 0.0" mesh="right_ankle.obj" />
                  <body name="RIGHT_FOOT" pos="0 0 -0.012" quat="1.0 0.0 0.0 0.0">
                    <joint name="RIGHT_ANKLE_X" type="hinge" range="-0.436332 0.436332" axis="1 0 0" />
                    <inertial pos="0.03793372 -0.00000219 -0.0443663" quat="1.0 0.0 0.0 0.0" mass="1.28288609" diaginertia="0.00131328 0.00385286 0.00406301" />
                    <geom name="RIGHT_FOOT_visual_0" class="visual" pos="0 0 0" quat="1.0 0.0 0.0 0.0" mesh="right_foot.obj" />
                    <body name="RIGHT_FOOT_IMU_LINK" pos="-0.03575526 0.01180178 -0.04979705" quat="0.7071068967259818 0.0 0.0 0.7071066656470943">
                      <inertial pos="0 0 0" quat="1.0 0.0 0.0 0.0" mass="0" diaginertia="0.0 0.0 0.0" />
                      <site name="RIGHT_FOOT_IMU_LINK_site" pos="-0.04979705 0.01180178 -0.03575526" quat="0.7071069 0.0 0.0 0.7071067" size="0.01" />
                    </body>
                  </body>
                </body>
                <body name="RIGHT_SHIN_IMU_LINK" pos="0.05673025 -0.00875818 -0.15674961" quat="0.5399826309812834 0.456529212248219 -0.45652906305682667 -0.5399824545177442">
                  <inertial pos="0 0 0" quat="1.0 0.0 0.0 0.0" mass="0" diaginertia="0.0 0.0 0.0" />
                  <site name="RIGHT_SHIN_IMU_LINK_site" pos="-0.15674961 -0.00875818 0.0" quat="0.5399826 0.4565292 0.4565291 -0.5399825" size="0.01" />
                </body>
              </body>
              <body name="RIGHT_THIGH_IMU_LINK" pos="0.10003618 -0.033541826 -0.21194191" quat="0.4680657519331888 0.5300137878061918 0.5300136146004192 0.46806559897171474">
                <inertial pos="0 0 0" quat="1.0 0.0 0.0 0.0" mass="0" diaginertia="0.0 0.0 0.0" />
                <site name="RIGHT_THIGH_IMU_LINK_site" pos="-0.21194191 -0.033541826 0.10003618" quat="0.7071069 0.0 0.0 0.7071067" size="0.01" />
              </body>
            </body>
          </body>
          <body name="RIGHT_HIP_X_IMU_LINK" pos="-0.01922309 -0.07694987 -0.01488788" quat="0.5000001633974483 -0.4999999999999733 -0.49999983660255165 0.4999999999999733">
            <inertial pos="0 0 0" quat="1.0 0.0 0.0 0.0" mass="0" diaginertia="0.0 0.0 0.0" />
            <site name="RIGHT_HIP_X_IMU_LINK_site" pos="-0.01488788 -0.07694987 -0.01922309" quat="0.5 -0.5 -0.5 -0.5" size="0.01" />
          </body>
        </body>
        
        <!-- Torso -->
        <body name="TORSO_LINK" pos="0.0 0 0.018" quat="1.0 0.0 0.0 0.0">
          <joint name="SPINE_Z" type="hinge" range="-0.5235987756 0.5235987756" axis="0 0 1" />
          <inertial pos="-0.034 0.0 0.297" quat="1.0 0.0 0.0 0.0" mass="4.208" diaginertia="0.077 0.068 0.033" />
          <geom name="TORSO_LINK_visual_0" class="visual" pos="0.0 0.0 0.0" quat="1.0 0.0 0.0 0.0" mesh="torso.obj" />

          <!-- Left arm -->
          <body name="LEFT_SHOULDER_Y_LINK" pos="-0.02 0.1 0.214" quat="0.9396925696192966 0.34202028390474665 0.0 0.0">
            <joint name="LEFT_SHOULDER_Y" type="hinge" range="-3.141592 1.22173" axis="0.0 1.0 0.0" />
            <inertial pos="-0.00264 0.12135 -0.006824" quat="1.0 0.0 0.0 0.0" mass="2.99" diaginertia="0.0111046 0.0051699 0.01176" />
            <geom name="LEFT_SHOULDER_Y_LINK_visual_0" class="visual" pos="0.0 0.0 0.0" quat="1.0 0.0 0.0 0.0" mesh="LeftShoulderPitchLink.obj" />
            <body name="LEFT_SHOULDER_X_LINK" pos="0.0 0.15676000 -0.01300000" quat="0.9396925696192966 -0.34202028390474665 0.0 0.0">
              <joint name="LEFT_SHOULDER_X" type="hinge" range="-0.349066 2.79253" axis="1 0 0" />
              <inertial pos="0.01251711 0.0188309 -0.03849849" quat="1.0 0.0 0.0 0.0" mass="0.972" diaginertia="0.0029485 0.0023587 0.0014366" />
              <geom name="LEFT_SHOULDER_X_LINK_visual_0" class="visual" pos="0.0 0.0 0.0" quat="1.0 0.0 0.0 0.0" mesh="LeftShoulderRollLink_shortBicep.obj" />
              <body name="LEFT_SHOULDER_Z_LINK" pos="0.0 0.035 0.0" quat="1.0 0.0 0.0 0.0">
                <joint name="LEFT_SHOULDER_Z" type="hinge" range="-1.91986 1.22173" axis="0.0 0.0 1.0" />
                <inertial pos="0.00510403 0.00314332 -0.21695413" quat="1.0 0.0 0.0 0.0" mass="2.91" diaginertia="0.0267829 0.0265514 0.003052" />
                <geom name="LEFT_SHOULDER_Z_LINK_visual_0" class="visual" pos="0.0 0.0 0.0867" quat="1.0 0.0 0.0 0.0" mesh="LeftShoulderYawLink.obj" />
                <body name="LEFT_ELBOW_Y_LINK" pos="0.015 0.0 -0.3127" quat="1.0 0.0 0.0 0.0">
                  <joint name="LEFT_ELBOW_Y" type="hinge" range="-2.35619 0.174532925" axis="0.0 1.0 0.0" />
                  <inertial pos="-0.01180322 -0.0035763 -0.04946747" quat="1.0 0.0 0.0 0.0" mass="0.45" diaginertia="0.0007362 0.0006567 0.0004897" />
                  <geom name="LEFT_ELBOW_Y_LINK_visual_0" class="visual" pos="0.0 0.0 0.0" quat="1.0 0.0 0.0 0.0" mesh="LeftElbowPitchLink.obj" />

                  <!-- Left hand -->
                  <body name="LEFT_WRIST_Z_LINK" pos="-0.015 0.0 0.0" quat="1.0 0.0 0.0 0.0">
                    <joint name="LEFT_WRIST_Z" type="hinge" range="-2.61799 2.61799" axis="0.0 0.0 1.0" />
                    <inertial pos="-0.00263832 -0.00050534 -0.13018376" quat="1.0 0.0 0.0 0.0" mass="1.547" diaginertia="0.0037869 0.004071 0.0015203" />
                    <geom name="LEFT_WRIST_Z_LINK_visual_0" class="visual" pos="0.0 0.0 0.0" quat="1.0 0.0 0.0 0.0" mesh="LeftWristYawLink.obj" />
                    <body name="LEFT_WRIST_X_LINK" pos="0.0 -0.013 -0.25" quat="1.0 0.0 0.0 0.0">
                      <joint name="LEFT_WRIST_X" type="hinge" range="-1.8326 0.610865" axis="1 0 0" />
                      <inertial pos="0.00004053 0.01038395 0.00035532" quat="1.0 0.0 0.0 0.0" mass="0.909" diaginertia="0.000477 0.0004902 0.000514" />
                      <geom name="LEFT_WRIST_X_LINK_visual_0" class="visual" pos="0.0 0.0 0.0" quat="1.0 0.0 0.0 0.0" mesh="LeftWristRollLink.obj" />
                      <body name="LEFT_GRIPPER_Z_LINK" pos="0.0 0.013 -0.031" quat="1.0 0.0 0.0 0.0">
                        <joint name="LEFT_GRIPPER_Z" type="hinge" range="-2.61799 2.61799" axis="0.0 0.0 1.0" />
                        <inertial pos="-0.000217 -0.000349 0.009761" quat="1.0 0.0 0.0 0.0" mass="0.251" diaginertia="7.22e-05 7.47e-05 3.24e-05" />
                        <geom name="LEFT_GRIPPER_Z_LINK_visual_0" class="visual" pos="0.0 0.0 0.0" quat="0.7073882691671998 0.0 0.706825181105366 0.0" mesh="nub.obj" />
                        <body name="LEFT_GRIPPER_ATTACHMENT_FIXED_LINK" pos="0 0 -0.02560000" quat="3.2679489653813835e-07 0.9999999999999466 0.0 0.0">
                          <inertial pos="22.41911e-3 -0.15798201e-3 -0.01319866e-3" quat="1.0 0.0 0.0 0.0" mass="1.00" diaginertia="0.00097826 0.00124478 0.00045622" />
                          <geom name="LEFT_GRIPPER_ATTACHMENT_FIXED_LINK_visual_0" pos="0 0 0" quat="1.0 0.0 0.0 0.0" material="default_material" type="mesh" mesh="wristmesh.obj" />
                        </body>
                      </body>
                    </body>
                  </body>
                </body>
              </body>
            </body>
          </body>
          
          <!-- Neck -->
          <body name="NECK_Z_LINK" pos="0.005 0 0.307953" quat="1.0 0.0 0.0 0.0">
            <joint name="NECK_Z" type="hinge" range="-1.5708 1.5708" axis="0 0 1" />
            <inertial pos="0.007143 0.006943 0.109823" quat="1.0 0.0 0.0 0.0" mass="1.141" diaginertia="0.007475898 0.007407578 0.00109269" />
            <geom name="NECK_Z_LINK_visual_0" pos="0 0 -0.05" quat="1.0 0.0 0.0 0.0" material="gray" type="cylinder" size="0.05 0.28" />
            <body name="HEAD_LINK" pos="0.025 0.01 0.207252" quat="1.0 0.0 0.0 0.0">
              <joint name="NECK_Y" type="hinge" range="-1.0472 1.0472" axis="0 1 0" />
              <inertial pos="0.03237 -0.013568 0.007163" quat="1.0 0.0 0.0 0.0" mass="1.677" diaginertia="0.006026191 0.008182071 0.00644909" />
              <geom name="HEAD_LINK_visual_0" pos="0.0 0.0 0.0" quat="1.0 0.0 0.0 0.0" material="default_material" type="mesh" mesh="head.obj" />
            </body>
          </body>

          <!-- Right arm -->
          <body name="RIGHT_SHOULDER_Y_LINK" pos="-0.02 -0.1 0.214" quat="0.9396925696192966 -0.34202028390474665 0.0 0.0">
            <joint name="RIGHT_SHOULDER_Y" type="hinge" range="-3.141592 1.22173" axis="0.0 1.0 0.0" />
            <inertial pos="-0.00264 -0.12135 -0.006824" quat="1.0 0.0 0.0 0.0" mass="2.99" diaginertia="0.0110394 0.0051097 0.0116925" />
            <geom name="RIGHT_SHOULDER_Y_LINK_visual_0" class="visual" pos="0.0 0.0 0.0" quat="1.0 0.0 0.0 0.0" mesh="RightShoulderPitchLink.obj" />
            <body name="RIGHT_SHOULDER_X_LINK" pos="0.0 -0.15676000 -0.01300000" quat="0.9396925696192966 0.34202028390474665 0.0 0.0">
              <joint name="RIGHT_SHOULDER_X" type="hinge" range="-2.79253 0.349066" axis="1 0 0" />
              <inertial pos="0.012489 -0.01882 -0.0385" quat="1.0 0.0 0.0 0.0" mass="0.972" diaginertia="0.002949 0.0023603 0.0014377" />
              <geom name="RIGHT_SHOULDER_X_LINK_visual_0" class="visual" pos="0.0 0.0 0.0" quat="1.0 0.0 0.0 0.0" mesh="RightShoulderRollLink_shortBicep.obj" />
              <body name="RIGHT_SHOULDER_Z_LINK" pos="0.0 -0.035 0.0" quat="1.0 0.0 0.0 0.0">
                <joint name="RIGHT_SHOULDER_Z" type="hinge" range="-1.22173 1.91986" axis="0.0 0.0 1.0" />
                <inertial pos="0.00524 -0.00274 -0.21745" quat="1.0 0.0 0.0 0.0" mass="2.91" diaginertia="0.0248699 0.0245973 0.0029883" />
                <geom name="RIGHT_SHOULDER_Z_LINK_visual_0" class="visual" pos="0.0 0.0 0.0867" quat="1.0 0.0 0.0 0.0" mesh="RightShoulderYawLink.obj" />
                <body name="RIGHT_ELBOW_Y_LINK" pos="0.015 0.0 -0.3127" quat="1.0 0.0 0.0 0.0">
                  <joint name="RIGHT_ELBOW_Y" type="hinge" range="-2.35619 0.174532925" axis="0.0 1.0 0.0" />
                  <inertial pos="-0.0127 0.006913 -0.048421" quat="1.0 0.0 0.0 0.0" mass="0.45" diaginertia="0.0006446 0.000625 0.0003922" />
                  <geom name="RIGHT_ELBOW_Y_LINK_visual_0" class="visual" pos="0.0 0.0 0.0" quat="1.0 0.0 0.0 0.0" mesh="RightElbowPitchLink.obj" />

                  <!-- Right hand -->
                  <body name="RIGHT_WRIST_Z_LINK" pos="-0.015 0.0 0.0" quat="1.0 0.0 0.0 0.0">
                    <joint name="RIGHT_WRIST_Z" type="hinge" range="-2.61799 2.61799" axis="0.0 0.0 1.0" />
                    <inertial pos="-0.002616 0.000462 -0.13019" quat="1.0 0.0 0.0 0.0" mass="1.547" diaginertia="0.0037805 0.0040639 0.0015151" />
                    <geom name="RIGHT_WRIST_Z_LINK_visual_0" class="visual" pos="0.0 0.0 0.0" quat="1.0 0.0 0.0 0.0" mesh="RightWristYawLink.obj" />
                    <body name="RIGHT_WRIST_X_LINK" pos="0.0 0.013 -0.25" quat="1.0 0.0 0.0 0.0">
                      <joint name="RIGHT_WRIST_X" type="hinge" range="-0.610865 1.8326" axis="1 0 0" />
                      <inertial pos="-0.0000481 -0.012143 0.000196" quat="1.0 0.0 0.0 0.0" mass="0.909" diaginertia="0.0005535 0.0005559 0.0005893" />
                      <geom name="RIGHT_WRIST_X_LINK_visual_0" class="visual" pos="0.0 0.0 0.0" quat="1.0 0.0 0.0 0.0" mesh="RightWristRollLink.obj" />
                      <body name="RIGHT_GRIPPER_Z_LINK" pos="0.0 -0.013 -0.031" quat="1.0 0.0 0.0 0.0">
                        <joint name="RIGHT_GRIPPER_Z" type="hinge" range="-2.61799 2.61799" axis="0.0 0.0 1.0" />
                        <inertial pos="-0.000217 -0.000349 0.009761" quat="1.0 0.0 0.0 0.0" mass="0.251" diaginertia="7.22e-05 7.47e-05 3.24e-05" />
                        <geom name="RIGHT_GRIPPER_Z_LINK_visual_0" class="visual" pos="0.0 0.0 0.0" quat="0.7073882691671998 0.0 0.706825181105366 0.0" mesh="nub.obj" />
                        <body name="RIGHT_GRIPPER_ATTACHMENT_FIXED_LINK" pos="0 0 -0.02560000" quat="1.0679490440337254e-13 -3.267948965381209e-07 -0.9999999999998932 3.267948965381209e-07">
                          <inertial pos="22.41911e-3 -0.15798201e-3 -0.01319866e-3" quat="1.0 0.0 0.0 0.0" mass="1.00" diaginertia="0.00097826 0.00124478 0.00045622" />
                          <geom name="RIGHT_GRIPPER_ATTACHMENT_FIXED_LINK_visual_0" class="visual" pos="0 0 0" quat="1.0 0.0 0.0 0.0" mesh="wristmesh.obj" />
                        </body>
                      </body>
                    </body>
                  </body>
                </body>
              </body>
            </body>
          </body>
        </body>
        <body name="PELVIS_STIM_IMU_LINK" pos="-0.08687724 0.01225028 -0.08051472" quat="0.7071068967259818 0.0 0.0 0.7071066656470943">
          <inertial pos="0 0 0" quat="1.0 0.0 0.0 0.0" mass="0.0" diaginertia="0.0 0.0 0.0" />
          <site name="PELVIS_STIM_IMU_LINK_site" pos="-0.08051472 0.01225028 -0.08687724" quat="0.7071069 0.0 0.0 0.7071067" size="0.01" />
        </body>
      </body>
    </body>
  </worldbody>

  <actuator>
    <position name="LEFT_HIP_X_ctrl" joint="LEFT_HIP_X" kp="40.00000000" kv="2.00000000" forcerange="-150.00000000 150.00000000" forcelimited="true" ctrlrange="-0.3490658504 0.872664626" ctrllimited="true" />
    <position name="LEFT_HIP_Z_ctrl" joint="LEFT_HIP_Z" kp="40.00000000" kv="2.00000000" forcerange="-60.00000000 60.00000000" forcelimited="true" ctrlrange="-0.3490658504 1.0472" ctrllimited="true" />
    <position name="LEFT_HIP_Y_ctrl" joint="LEFT_HIP_Y" kp="40.00000000" kv="2.00000000" forcerange="-200.00000000 200.00000000" forcelimited="true" ctrlrange="-2.61799 0.785398" ctrllimited="true" />
    <position name="LEFT_KNEE_Y_ctrl" joint="LEFT_KNEE_Y" kp="40.00000000" kv="2.00000000" forcerange="-200.00000000 200.00000000" forcelimited="true" ctrlrange="0.0 2.445206282" ctrllimited="true" />
    <position name="LEFT_ANKLE_Y_ctrl" joint="LEFT_ANKLE_Y" kp="40.00000000" kv="2.00000000" forcerange="-180.00000000 180.00000000" forcelimited="true" ctrlrange="-1.0472 0.523599" ctrllimited="true" />
    <position name="LEFT_ANKLE_X_ctrl" joint="LEFT_ANKLE_X" kp="40.00000000" kv="2.00000000" forcerange="-90.00000000 90.00000000" forcelimited="true" ctrlrange="-0.436332 0.436332" ctrllimited="true" />
    <position name="RIGHT_HIP_X_ctrl" joint="RIGHT_HIP_X" kp="40.00000000" kv="2.00000000" forcerange="-150.00000000 150.00000000" forcelimited="true" ctrlrange="-0.872664626 0.3490658504" ctrllimited="true" />
    <position name="RIGHT_HIP_Z_ctrl" joint="RIGHT_HIP_Z" kp="40.00000000" kv="2.00000000" forcerange="-60.00000000 60.00000000" forcelimited="true" ctrlrange="-1.0472 0.3490658504" ctrllimited="true" />
    <position name="RIGHT_HIP_Y_ctrl" joint="RIGHT_HIP_Y" kp="40.00000000" kv="2.00000000" forcerange="-200.00000000 200.00000000" forcelimited="true" ctrlrange="-2.61799 0.785398" ctrllimited="true" />
    <position name="RIGHT_KNEE_Y_ctrl" joint="RIGHT_KNEE_Y" kp="40.00000000" kv="2.00000000" forcerange="-200.00000000 200.00000000" forcelimited="true" ctrlrange="0.0 2.445206282" ctrllimited="true" />
    <position name="RIGHT_ANKLE_Y_ctrl" joint="RIGHT_ANKLE_Y" kp="40.00000000" kv="2.00000000" forcerange="-180.00000000 180.00000000" forcelimited="true" ctrlrange="-1.0472 0.523599" ctrllimited="true" />
    <position name="RIGHT_ANKLE_X_ctrl" joint="RIGHT_ANKLE_X" kp="40.00000000" kv="2.00000000" forcerange="-90.00000000 90.00000000" forcelimited="true" ctrlrange="-0.436332 0.436332" ctrllimited="true" />
    <position name="SPINE_Z_ctrl" joint="SPINE_Z" kp="40.00000000" kv="2.00000000" forcerange="-150.00000000 150.00000000" forcelimited="true" ctrlrange="-0.5235987756 0.5235987756" ctrllimited="true" />
    <position name="LEFT_SHOULDER_Y_ctrl" joint="LEFT_SHOULDER_Y" kp="40.00000000" kv="2.00000000" forcerange="-150.00000000 150.00000000" forcelimited="true" ctrlrange="-3.141592 1.22173" ctrllimited="true" />
    <position name="LEFT_SHOULDER_X_ctrl" joint="LEFT_SHOULDER_X" kp="40.00000000" kv="2.00000000" forcerange="-150.00000000 150.00000000" forcelimited="true" ctrlrange="-0.349066 2.79253" ctrllimited="true" />
    <position name="LEFT_SHOULDER_Z_ctrl" joint="LEFT_SHOULDER_Z" kp="40.00000000" kv="2.00000000" forcerange="-80.00000000 80.00000000" forcelimited="true" ctrlrange="-1.91986 1.22173" ctrllimited="true" />
    <position name="LEFT_ELBOW_Y_ctrl" joint="LEFT_ELBOW_Y" kp="40.00000000" kv="2.00000000" forcerange="-80.00000000 80.00000000" forcelimited="true" ctrlrange="-2.35619 0.174532925" ctrllimited="true" />
    <position name="LEFT_WRIST_Z_ctrl" joint="LEFT_WRIST_Z" kp="40.00000000" kv="2.00000000" forcerange="-20.00000000 20.00000000" forcelimited="true" ctrlrange="-2.61799 2.61799" ctrllimited="true" />
    <position name="LEFT_WRIST_X_ctrl" joint="LEFT_WRIST_X" kp="40.00000000" kv="2.00000000" forcerange="-20.00000000 20.00000000" forcelimited="true" ctrlrange="-1.8326 0.610865" ctrllimited="true" />
    <position name="LEFT_GRIPPER_Z_ctrl" joint="LEFT_GRIPPER_Z" kp="40.00000000" kv="2.00000000" forcerange="-20.00000000 20.00000000" forcelimited="true" ctrlrange="-2.61799 2.61799" ctrllimited="true" />
    <position name="NECK_Z_ctrl" joint="NECK_Z" kp="40.00000000" kv="2.00000000" forcerange="-20.00000000 20.00000000" forcelimited="true" ctrlrange="-1.5708 1.5708" ctrllimited="true" />
    <position name="NECK_Y_ctrl" joint="NECK_Y" kp="40.00000000" kv="2.00000000" forcerange="-20.00000000 20.00000000" forcelimited="true" ctrlrange="-1.0472 1.0472" ctrllimited="true" />
    <position name="RIGHT_SHOULDER_Y_ctrl" joint="RIGHT_SHOULDER_Y" kp="40.00000000" kv="2.00000000" forcerange="-1000.00000000 1000.00000000" forcelimited="true" ctrlrange="-3.141592 1.22173" ctrllimited="true" />
    <position name="RIGHT_SHOULDER_X_ctrl" joint="RIGHT_SHOULDER_X" kp="40.00000000" kv="2.00000000" forcerange="-1000.00000000 1000.00000000" forcelimited="true" ctrlrange="-2.79253 0.349066" ctrllimited="true" />
    <position name="RIGHT_SHOULDER_Z_ctrl" joint="RIGHT_SHOULDER_Z" kp="40.00000000" kv="2.00000000" forcerange="-1000.00000000 1000.00000000" forcelimited="true" ctrlrange="-1.22173 1.91986" ctrllimited="true" />
    <position name="RIGHT_ELBOW_Y_ctrl" joint="RIGHT_ELBOW_Y" kp="40.00000000" kv="2.00000000" forcerange="-1000.00000000 1000.00000000" forcelimited="true" ctrlrange="-2.35619 0.174532925" ctrllimited="true" />
    <position name="RIGHT_WRIST_Z_ctrl" joint="RIGHT_WRIST_Z" kp="40.00000000" kv="2.00000000" forcerange="-20.00000000 20.00000000" forcelimited="true" ctrlrange="-2.61799 2.61799" ctrllimited="true" />
    <position name="RIGHT_WRIST_X_ctrl" joint="RIGHT_WRIST_X" kp="40.00000000" kv="2.00000000" forcerange="-20.00000000 20.00000000" forcelimited="true" ctrlrange="-0.610865 1.8326" ctrllimited="true" />
    <position name="RIGHT_GRIPPER_Z_ctrl" joint="RIGHT_GRIPPER_Z" kp="40.00000000" kv="2.00000000" forcerange="-20.00000000 20.00000000" forcelimited="true" ctrlrange="-2.61799 2.61799" ctrllimited="true" />
  </actuator>

  <sensor>
    <framepos name="base_link_pos" objtype="site" objname="root_site" />
    <framequat name="base_link_quat" objtype="site" objname="root_site" />
    <framelinvel name="base_link_vel" objtype="site" objname="root_site" />
    <frameangvel name="base_link_ang_vel" objtype="site" objname="root_site" />
    <accelerometer name="PELVIS_STIM_IMU_LINK_acc" site="PELVIS_STIM_IMU_LINK_site" noise="0.017" />
    <gyro name="PELVIS_STIM_IMU_LINK_gyro" site="PELVIS_STIM_IMU_LINK_site" noise="0.0002" />
    <magnetometer name="PELVIS_STIM_IMU_LINK_mag" site="PELVIS_STIM_IMU_LINK_site" />
    <accelerometer name="LEFT_HIP_X_IMU_LINK_acc" site="LEFT_HIP_X_IMU_LINK_site" noise="0.017" />
    <gyro name="LEFT_HIP_X_IMU_LINK_gyro" site="LEFT_HIP_X_IMU_LINK_site" noise="0.0002" />
    <magnetometer name="LEFT_HIP_X_IMU_LINK_mag" site="LEFT_HIP_X_IMU_LINK_site" />
    <accelerometer name="LEFT_THIGH_IMU_LINK_acc" site="LEFT_THIGH_IMU_LINK_site" noise="0.017" />
    <gyro name="LEFT_THIGH_IMU_LINK_gyro" site="LEFT_THIGH_IMU_LINK_site" noise="0.0002" />
    <magnetometer name="LEFT_THIGH_IMU_LINK_mag" site="LEFT_THIGH_IMU_LINK_site" />
    <accelerometer name="LEFT_SHIN_IMU_LINK_acc" site="LEFT_SHIN_IMU_LINK_site" noise="0.017" />
    <gyro name="LEFT_SHIN_IMU_LINK_gyro" site="LEFT_SHIN_IMU_LINK_site" noise="0.0002" />
    <magnetometer name="LEFT_SHIN_IMU_LINK_mag" site="LEFT_SHIN_IMU_LINK_site" />
    <accelerometer name="LEFT_FOOT_IMU_LINK_acc" site="LEFT_FOOT_IMU_LINK_site" noise="0.017" />
    <gyro name="LEFT_FOOT_IMU_LINK_gyro" site="LEFT_FOOT_IMU_LINK_site" noise="0.0002" />
    <magnetometer name="LEFT_FOOT_IMU_LINK_mag" site="LEFT_FOOT_IMU_LINK_site" />
    <accelerometer name="RIGHT_HIP_X_IMU_LINK_acc" site="RIGHT_HIP_X_IMU_LINK_site" noise="0.017" />
    <gyro name="RIGHT_HIP_X_IMU_LINK_gyro" site="RIGHT_HIP_X_IMU_LINK_site" noise="0.0002" />
    <magnetometer name="RIGHT_HIP_X_IMU_LINK_mag" site="RIGHT_HIP_X_IMU_LINK_site" />
    <accelerometer name="RIGHT_THIGH_IMU_LINK_acc" site="RIGHT_THIGH_IMU_LINK_site" noise="0.017" />
    <gyro name="RIGHT_THIGH_IMU_LINK_gyro" site="RIGHT_THIGH_IMU_LINK_site" noise="0.0002" />
    <magnetometer name="RIGHT_THIGH_IMU_LINK_mag" site="RIGHT_THIGH_IMU_LINK_site" />
    <accelerometer name="RIGHT_SHIN_IMU_LINK_acc" site="RIGHT_SHIN_IMU_LINK_site" noise="0.017" />
    <gyro name="RIGHT_SHIN_IMU_LINK_gyro" site="RIGHT_SHIN_IMU_LINK_site" noise="0.0002" />
    <magnetometer name="RIGHT_SHIN_IMU_LINK_mag" site="RIGHT_SHIN_IMU_LINK_site" />
    <accelerometer name="RIGHT_FOOT_IMU_LINK_acc" site="RIGHT_FOOT_IMU_LINK_site" noise="0.017" />
    <gyro name="RIGHT_FOOT_IMU_LINK_gyro" site="RIGHT_FOOT_IMU_LINK_site" noise="0.0002" />
    <magnetometer name="RIGHT_FOOT_IMU_LINK_mag" site="RIGHT_FOOT_IMU_LINK_site" />
  </sensor>
</mujoco>