<mujoco model="Alexander">
  <default>
    <joint limited="true" damping="0.01" armature="0.01" frictionloss="0.01" />
    <geom condim="4" contype="1" conaffinity="15" friction="0.9 0.2 0.2" solref="0.001 2" />
    <motor ctrllimited="true" />
    <equality solref="0.001 2" />
    <default class="visualgeom">
      <geom material="visualgeom" condim="1" contype="0" conaffinity="0" />
    </default>
  </default>

  <compiler angle="radian" meshdir="../meshes/" eulerseq="zyx" autolimits="true" />

  <asset>
    <texture name="texplane" type="2d" builtin="checker" rgb1=".0 .0 .0" rgb2=".8 .8 .8" width="100" height="100" />
    <material name="matplane" reflectance="0." texture="texplane" texrepeat="1 1" texuniform="true" />
    <material name="default_material" rgba="0.7 0.7 0.7 1" />
    <mesh name="RightShoulderPitchLink.obj" file="cycloidal_arm/RightShoulderPitchLink.obj" />
    <mesh name="RightShoulderRollLink_shortBicep.obj" file="cycloidal_arm/RightShoulderRollLink_shortBicep.obj" />
    <mesh name="RightShoulderYawLink.obj" file="cycloidal_arm/RightShoulderYawLink.obj" />
    <mesh name="RIGHT_ELBOW_PITCH_LINK_413mm_LENGTH.obj" file="cycloidal_arm/RIGHT_ELBOW_PITCH_LINK_413mm_LENGTH.obj" />
  </asset>

  <worldbody>
    <light directional="true" diffuse="0.4 0.4 0.4" specular="0.1 0.1 0.1" pos="0 0 5.0" dir="0 0 -1" castshadow="false" />
    <light directional="true" diffuse="0.6 0.6 0.6" specular="0.2 0.2 0.2" pos="0 0 4" dir="0 0 -1" />
    <geom name="ground" type="plane" pos="0 0 0" size="10 10 0.001" quat="1 0 0 0" material="matplane" condim="3" conaffinity="15" />
    <body name="root" pos="0 0 0.05" quat="1 0 1 0">
      <freejoint name="root" />
      <site name="root_site" pos="0 0 0" quat="1 0 0 0" />
      <body name="TORSO_LINK" pos="0 0 0" quat="1 0 0 0">
        <inertial pos="0 0 0" quat="1.0 0.0 0.0 0.0" mass="0.001" diaginertia="1e-05 1e-05 1e-05" />
        <body name="RIGHT_SHOULDER_Y_LINK" pos="-0.025 -0.1 0.214" quat="0.9396925696192966 -0.34202028390474665 0.0 0.0">
          <joint name="RIGHT_SHOULDER_Y" type="hinge" range="-3.141592 1.22173" axis="0.0 1.0 0.0" />
          <inertial pos="-0.00264 -0.12135 -0.006824" quat="1.0 0.0 0.0 0.0" mass="2.99" diaginertia="0.0110394 0.0051097 0.0116925" />
          <geom name="RIGHT_SHOULDER_Y_LINK_visual_0" pos="0.0 0.0 0.0" quat="1.0 0.0 0.0 0.0" material="default_material" type="mesh" mesh="RightShoulderPitchLink.obj" />
          <body name="RIGHT_SHOULDER_X_LINK" pos="0.0 -0.15676000 -0.01300000" quat="0.9396925696192966 0.34202028390474665 0.0 0.0">
            <joint name="RIGHT_SHOULDER_X" type="hinge" range="-2.79253 0.349066" axis="1 0 0" />
            <inertial pos="0.012489 -0.01882 -0.0385" quat="1.0 0.0 0.0 0.0" mass="0.972" diaginertia="0.002949 0.0023603 0.0014377" />
            <geom name="RIGHT_SHOULDER_X_LINK_visual_0" pos="0.0 0.0 0.0" quat="1.0 0.0 0.0 0.0" material="default_material" type="mesh" mesh="RightShoulderRollLink_shortBicep.obj" />
            <body name="RIGHT_SHOULDER_Z_LINK" pos="0.0 -0.035 0.0" quat="1.0 0.0 0.0 0.0">
              <joint name="RIGHT_SHOULDER_Z" type="hinge" range="-1.22173 1.91986" axis="0.0 0.0 1.0" />
              <inertial pos="0.00524 -0.00274 -0.21745" quat="1.0 0.0 0.0 0.0" mass="2.91" diaginertia="0.0248699 0.0245973 0.0029883" />
              <geom name="RIGHT_SHOULDER_Z_LINK_visual_0" pos="0.0 0.0 0.0867" quat="1.0 0.0 0.0 0.0" material="default_material" type="mesh" mesh="RightShoulderYawLink.obj" />
              <body name="RIGHT_ELBOW_PITCH_LINK" pos="0.015 0.0 -0.3127" quat="1.0 0.0 0.0 0.0">
                <joint name="RIGHT_ELBOW_Y" type="hinge" range="-2.35619 0.174532925" axis="0.0 1.0 0.0" />
                <inertial pos="-0.01090935 0.01147189 -0.10388715" quat="1.0 0.0 0.0 0.0" mass="0.616" diaginertia="0.00760733 0.00767556 0.0004554" />
                <geom name="RIGHT_ELBOW_PITCH_LINK_visual_0" pos="0.0 0.0 0.0" quat="1.0 0.0 0.0 0.0" material="default_material" type="mesh" mesh="RIGHT_ELBOW_PITCH_LINK_413mm_LENGTH.obj" />
              </body>
            </body>
          </body>
        </body>
      </body>
    </body>
  </worldbody>

  <actuator>
    <position name="RIGHT_SHOULDER_Y_ctrl" joint="RIGHT_SHOULDER_Y" kp="40.00000000" kv="2.00000000" forcerange="-1000.00000000 1000.00000000" forcelimited="true" ctrlrange="-3.141592 1.22173" ctrllimited="true" />
    <position name="RIGHT_SHOULDER_X_ctrl" joint="RIGHT_SHOULDER_X" kp="40.00000000" kv="2.00000000" forcerange="-1000.00000000 1000.00000000" forcelimited="true" ctrlrange="-2.79253 0.349066" ctrllimited="true" />
    <position name="RIGHT_SHOULDER_Z_ctrl" joint="RIGHT_SHOULDER_Z" kp="40.00000000" kv="2.00000000" forcerange="-1000.00000000 1000.00000000" forcelimited="true" ctrlrange="-1.22173 1.91986" ctrllimited="true" />
    <position name="RIGHT_ELBOW_Y_ctrl" joint="RIGHT_ELBOW_Y" kp="40.00000000" kv="2.00000000" forcerange="-1000.00000000 1000.00000000" forcelimited="true" ctrlrange="-2.35619 0.174532925" ctrllimited="true" />
  </actuator>

  <sensor>
    <framepos name="base_link_pos" objtype="site" objname="root_site" />
    <framequat name="base_link_quat" objtype="site" objname="root_site" />
    <framelinvel name="base_link_vel" objtype="site" objname="root_site" />
    <frameangvel name="base_link_ang_vel" objtype="site" objname="root_site" />
  </sensor>
</mujoco>