<?xml version = "1.0" ?>
<robot name="Alexander">


        <!-- NECK & HEAD LINKS -->
        <joint name="NECK_Z" type="revolute">
            <origin rpy="0 0 0" xyz="0 0 0.307953"/> <!-- placeholder for the joint location -->
            <axis xyz="0 0 1"/>
            <parent link="TORSO_LINK"/>
            <child link="NECK_Z_LINK"/>
            <limit effort="20" lower="-1.5708" upper="1.5708" velocity="20"/>
            <dynamics damping="0.05" friction="0.0"/>
        </joint>
        <joint name="NECK_Y" type="revolute">
            <origin rpy="0 0 0" xyz="0.025 0.01 0.207252"/>
            <axis xyz="0 1 0"/>
            <parent link="NECK_Z_LINK"/>
            <child link="HEAD_LINK"/>
            <limit effort="20" lower="-1.0472" upper="1.0472" velocity="20"/>
            <dynamics damping="0.05" friction="0.0"/>
        </joint>-->

        <!-- NECK & HEAD LINKS -->

       <link name="NECK_Z_LINK">
            <inertial>
                <mass value="1.141"/>
                <origin rpy="0 0 0" xyz="0.007143 0.006943 0.109823"/>
                <inertia ixx="0.007475898" ixy="-0.000075723" ixz="-0.000745362" iyy="0.007407578" iyz="-0.000436948" izz="0.00109269"/>
            </inertial>
            <visual>
                <geometry>
                    <cylinder radius="0.05" length="0.1"/>
                </geometry>
                <material name="gray">
                    <color rgba="0.5 0.5 0.5 1.0"/>
                </material>
                <origin rpy="0.0 0.0 0.0" xyz="0 0 0.0"/>
            </visual>
        </link>
        <link name="HEAD_LINK">
            <inertial>
                <mass value="1.677"/>
                <origin rpy="0 0 0" xyz="0.03237 -0.013568 0.007163"/>
                <inertia ixx="0.006026191" ixy="-0.000197484" ixz="0.001813659" iyy="0.008182071" iyz="-0.000042529" izz="0.00644909"/>
            </inertial>
            <visual>
                <geometry>
                    <mesh filename="package://alexander_V1_description/meshes/ALX02_01_A02_HeadLink.obj"/>
                </geometry>
                <origin rpy="0.0 0.0 0.0" xyz="0.0 0.0 0.0"/>
            </visual>
        </link>-

</robot>
